package Exception_Handling;

public class Try_catch_finally_23 {

	public static void main(String[] args) {
try {

	int a=1/1;
	System.out.println("under range");
	}
catch(java.util.InputMismatchException lovely)
{
	System.out.println("error occur");
}
finally
{
	System.out.println("job");
}
}
}

	


